GTCEuStartupEvents.registry('gtceu:machine', event => {
    event.create('komaru_frame_test', 'multiblock')
    .recipeType('dummy') 
    .pattern(definition => FactoryBlockPattern.start()
        .aisle("                           BBBBBBBBB                           ", "                             B   B                             ", "                             B   B                             ", "                             B   B                             ", "                           BBBBBBBBB                           ", "                              C C                              ", "                              C C                              ", "                              CCC                              ", "                               C                               ", "                               C                               ", "                                                               ", "                                                               ", "                                                               ", "                                                               ", "                                                               ", "                                                               ", "                                                               ", "                                                               ", "                                                               ", "                                                               ", "                                                               ", "                                                               ", "                                                               ", "                                                               ", "                                                               ", "                                                               ", "                                                               ", "                                                               ", "                                                               ", "                                                               ", "                                                               ", "                                                               ", "                                                               ", "                                                               ", "                                                               ", "                                                               ", "                                                               ", "                                                               ", "                                                               ", "                                                               ", "                                                               ", "                                                               ", "                                                               ", "                                                               ", "                                                               ", "                                                               ", "                                                               ", "                                                               ", "                                                               ", "                                                               ", "                                                               ", "                                                               ", "                                                               ", "                                                               ", "                                                               ", "                                                               ", "                                                               ", "                                                               ", "                                                               ", "                                                               ", "                                                               ", "                                                               ", "                                                               ") 
        .aisle("           BBBBBBB    BBBBBDDDBEBDDDBBBBB    BBBBBBB           ", "                           CCD   DCC                           ", "                           CFD   DFC                           ", "                           CCD   DCC                           ", "                      BBBBBDDBCCCBDDBBBBB                      ", "                           BB GGG BB                           ", "                              GGG                              ", "                              GGG                              ", "                              GGG                              ", "                               C                               ", "                                                               ", "                                                               ", "                                                               ", "                                                               ", "                                                               ", "                                                               ", "                                                               ", "                                                               ", "                                                               ", "                                                               ", "                                                               ", "                                                               ", "                                                               ", "                                                               ", "                                                               ", "                                                               ", "                                                               ", "                                                               ", "                                                               ", "                                                               ", "                                                               ", "                                                               ", "                                                               ", "                                                               ", "                                                               ", "                                                               ", "                                                               ", "                                                               ", "                                                               ", "                                                               ", "                                                               ", "                                                               ", "                                                               ", "                                                               ", "                                                               ", "                                                               ", "                                                               ", "                                                               ", "                                                               ", "                                                               ", "                                                               ", "                                                               ", "                                                               ", "                                                               ", "                                                               ", "                                                               ", "                                                               ", "                                                               ", "                                                               ", "                                                               ", "                                                               ", "                                                               ", "                                                               ") 
        .aisle("         BBHHHHHHHBBBBDDDDDDDDBEBDDDDDDDDBBBBHHHHHHHBB         ", "                      CCCCCIID   DIICCCCC                      ", "                      CFCFCIJD   DJICFCFC                      ", "                      CCCCCIID   DIICCCCC                      ", "                    BBDDDDDDDBCKCBDDDDDDDBB                    ", "                      BBBBBBB GGG BBBBBBB                      ", "                           C  GGG  C                           ", "                              GGG                              ", "                              GGG                              ", "                               C                               ", "                                                               ", "                                                               ", "                                                               ", "                                                               ", "                                                               ", "                                                               ", "                                                               ", "                                                               ", "                                                               ", "                                                               ", "                                                               ", "                                                               ", "                                                               ", "                                                               ", "                                                               ", "                                                               ", "                                                               ", "                                                               ", "                                                               ", "                                                               ", "                                                               ", "                                                               ", "                                                               ", "                                                               ", "                                                               ", "                                                               ", "                                                               ", "                                                               ", "                                                               ", "                                                               ", "                                                               ", "                                                               ", "                                                               ", "                                                               ", "                                                               ", "                                                               ", "                                                               ", "                                                               ", "                                                               ", "                                                               ", "                                                               ", "                                                               ", "                                                               ", "                                                               ", "                                                               ", "                                                               ", "                                                               ", "                                                               ", "                                                               ", "                                                               ", "                                                               ", "                                                               ", "                                                               ") 
        .aisle("       BBHHHLLHHHBBBDDDDDDDMMMBEBMMMDDDDDDDBBBHHHLLHHHBB       ", "                    CCIIIIINNO   ONNIIIIICC                    ", "                    CFIJIJINNO   ONNIJIJIFC                    ", "                    CCIIIIINNO   ONNIIIIICC                    ", "                  BBDDDDDDDMMBCACBMMDDDDDDDBB                  ", "                    BBPPPPPPB GGG BPPPPPPBB                    ", "                       B   B  GGG  B   B                       ", "                           C  GGG  C                           ", "                           C  GGG  C                           ", "                           CCCCCCCCC                           ", "                             C   C                             ", "                                                               ", "                                                               ", "                                                               ", "                                                               ", "                                                               ", "                                                               ", "                                                               ", "                                                               ", "                                                               ", "                                                               ", "                                                               ", "                                                               ", "                                                               ", "                                                               ", "                                                               ", "                                                               ", "                                                               ", "                                                               ", "                                                               ", "                                                               ", "                                                               ", "                                                               ", "                                                               ", "                                                               ", "                                                               ", "                                                               ", "                                                               ", "                                                               ", "                                                               ", "                                                               ", "                                                               ", "                                                               ", "                                                               ", "                                                               ", "                                                               ", "                                                               ", "                                                               ", "                                                               ", "                                                               ", "                                                               ", "                                                               ", "                                                               ", "                                                               ", "                                                               ", "                                                               ", "                                                               ", "                                                               ", "                                                               ", "                                                               ", "                                                               ", "                                                               ", "                                                               ") 
        .aisle("      BHHHLLLHHBBBDDDDMMMMMMMMBEBMMMMMMMMDDDDBBBHHLLLHHHB      ", "                  CCIINNNNNNNO   ONNNNNNNIICC                  ", "                  CFIJNNNNNNNO   ONNNNNNNJIFC                  ", "                  CCIINNNNNNNO   ONNNNNNNIICC                  ", "                BBDDDDMMMMMMMBCCCBMMMMMMMDDDDBB                ", "                  BBPPPPPPPPB  C  BPPPPPPPPBB                  ", "                       B   B       B   B                       ", "                       C   B       B   C                       ", "                       C   B       B   C                       ", "                       CCCCBBBBBBBBBCCCC                       ", "                             C   C                             ", "                                                               ", "                                                               ", "                                                               ", "                                                               ", "                                                               ", "                                                               ", "                                                               ", "                                                               ", "                                                               ", "                                                               ", "                                                               ", "                                                               ", "                                                               ", "                                                               ", "                                                               ", "                                                               ", "                                                               ", "                                                               ", "                                                               ", "                                                               ", "                                                               ", "                                                               ", "                                                               ", "                                                               ", "                                                               ", "                                                               ", "                                                               ", "                                                               ", "                                                               ", "                                                               ", "                                                               ", "                                                               ", "                                                               ", "                                                               ", "                                                               ", "                                                               ", "                                                               ", "                                                               ", "                                                               ", "                                                               ", "                                                               ", "                                                               ", "                                                               ", "                                                               ", "                                                               ", "                                                               ", "                                                               ", "                                                               ", "                                                               ", "                                                               ", "                                                               ", "                                                               ") 
        .aisle("     BHHLLLLHHBBDDDDMMMMMMMDDDBEBDDDMMMMMMMDDDDBBHHLLLLHHB     ", "                CCIINNNNNNNIID   DIINNNNNNNIICC                ", "                CFIJNNNNNNNIID   DIINNNNNNNJIFC                ", "               CCCIINNNNNNNIID   DIINNNNNNNIICC                ", "              BBDDDDMMMMMMMDDBCCCBDDMMMMMMMDDDDBB              ", "                BBPPPPPPPPPPB GGG BPPPPPPPPPPBB                ", "                  B    BCCCB  GGG  BCCCB    B                  ", "                       BCFCB  GGG  BCFCB                       ", "                       BCCCB  GGG  BCCCB                       ", "                    CCCBBBBBHHHBHHHBBBBBCCC                    ", "                                                               ", "                             C   C                             ", "                                                               ", "                                                               ", "                                                               ", "                                                               ", "                                                               ", "                                                               ", "                                                               ", "                                                               ", "                                                               ", "                                                               ", "                                                               ", "                                                               ", "                                                               ", "                                                               ", "                                                               ", "                                                               ", "                                                               ", "                                                               ", "                                                               ", "                                                               ", "                                                               ", "                                                               ", "                                                               ", "                                                               ", "                                                               ", "                                                               ", "                                                               ", "                                                               ", "                                                               ", "                                                               ", "                                                               ", "                                                               ", "                                                               ", "                                                               ", "                                                               ", "                                                               ", "                                                               ", "                                                               ", "                                                               ", "                                                               ", "                                                               ", "                                                               ", "                                                               ", "                                                               ", "                                                               ", "                                                               ", "                                                               ", "                                                               ", "                                                               ", "                                                               ", "                                                               ") 
        .aisle("    BHHLLLLHHBDDDDMMMMMDDDDDDDBEBDDDDDDDMMMMMDDDDBHHLLLLHHB    ", "              CCIINNNNNIIIIDDD   DDDIIIINNNNNIICC              ", "               FIJNNNNNIIIIDDD   DDDIIIINNNNNJIF               ", "              CCIINNNNNIIIIDDD   DDDIIIINNNNNIICC              ", "             BDDDDMMMMMDDDDDDBCKCBDDDDDDMMMMMDDDDB             ", "              BBPPPPPPPPPPPPB GGG BPPPPPPPPPPPPBB              ", "                  B  CCBIIIB  GGG  BIIIBCC  B                  ", "                  C  FCBIJIB  GGG  BIJIBFC  C                  ", "                  C  CCBIIIB  GGG  BIIIBCC  C                  ", "                  CCBBBHHHHH  HBH  HHHHHBBBCC                  ", "                                                               ", "                             CC CC                             ", "                                                               ", "                                                               ", "                                                               ", "                                                               ", "                                                               ", "                                                               ", "                                                               ", "                                                               ", "                                                               ", "                                                               ", "                                                               ", "                                                               ", "                                                               ", "                                                               ", "                                                               ", "                                                               ", "                                                               ", "                                                               ", "                                                               ", "                                                               ", "                                                               ", "                                                               ", "                                                               ", "                                                               ", "                                                               ", "                                                               ", "                                                               ", "                                                               ", "                                                               ", "                                                               ", "                                                               ", "                                                               ", "                                                               ", "                                                               ", "                                                               ", "                                                               ", "                                                               ", "                                                               ", "                                                               ", "                                                               ", "                                                               ", "                                                               ", "                                                               ", "                                                               ", "                                                               ", "                                                               ", "                                                               ", "                                                               ", "                                                               ", "                                                               ", "                                                               ") 
        .aisle("   BHHLLLLHHBDDDMMMMMDDDDDDDDDBEBDDDDDDDDDMMMMMDDDBHHLLLLHHB   ", "             CCINNNNNIILLLDDDD   DDDDLLLIINNNNNICC             ", "              FJNNNNNIILLLDDDD   DDDDLLLIINNNNNJF              ", "             CCINNNNNIILLLDDDD   DDDDLLLIINNNNNICC             ", "            BDDDMMMMMDDDDDDDDBCACBDDDDDDDDMMMMMDDDB            ", "             BPPPPPPPPPBBBPPB GGG BPPBBBPPPPPPPPPB             ", "              B   BCCIIBBBBB  GGG  BBBBBIICCB   B              ", "                  BFCJIBBBBB  GGG  BBBBBJIFCB                  ", "                  BCCIIBBBBB  GGG  BBBBBIICCB                  ", "                 CBBBHH       HBH       HHBBBC                 ", "                                                               ", "                                                               ", "                             C C C                             ", "                                                               ", "                                                               ", "                                                               ", "                                                               ", "                                                               ", "                                                               ", "                                                               ", "                                                               ", "                                                               ", "                                                               ", "                                                               ", "                                                               ", "                                                               ", "                                                               ", "                                                               ", "                                                               ", "                                                               ", "                                                               ", "                                                               ", "                                                               ", "                                                               ", "                                                               ", "                                                               ", "                                                               ", "                                                               ", "                                                               ", "                                                               ", "                                                               ", "                                                               ", "                                                               ", "                                                               ", "                                                               ", "                                                               ", "                                                               ", "                                                               ", "                                                               ", "                                                               ", "                                                               ", "                                                               ", "                                                               ", "                                                               ", "                                                               ", "                                                               ", "                                                               ", "                                                               ", "                                                               ", "                                                               ", "                                                               ", "                                                               ", "                                                               ") 
        .aisle("   BHLLLLHHBDDDMMMMDDDDBBBDDDDBEBDDDDBBBDDDDMMMMDDDBHHLLLLHB   ", "            CCINNNNIILL   LDDD   DDDL   LLIINNNNICC            ", "             FINNNNIILL   LDDD   DDDL   LLIINNNNIF             ", "            CCINNNNIILL   LDDD   DDDL   LLIINNNNICC            ", "           BDDDMMMMDDDDBBBDDDBCCCBDDDBBBDDDDMMMMDDDB           ", "            BPPPPPPPPBB   BBB  C  BBB   BBPPPPPPPPB            ", "              B  CBIIBBFFFBB       BBFFFBBIIBC  B              ", "              C  CBJIBBC               CBBJIBC  C              ", "                 CBIIBB                 BBIIBC                 ", "               CCBHHH         HBH         HHHBCC               ", "                                                               ", "                                                               ", "                                                               ", "                             CC CC                             ", "                                                               ", "                                                               ", "                                                               ", "                                                               ", "                                                               ", "                                                               ", "                                                               ", "                                                               ", "                                                               ", "                                                               ", "                                                               ", "                                                               ", "                                                               ", "                                                               ", "                                                               ", "                                                               ", "                                                               ", "                                                               ", "                                                               ", "                                                               ", "                                                               ", "                                                               ", "                                                               ", "                                                               ", "                                                               ", "                                                               ", "                                                               ", "                                                               ", "                                                               ", "                                                               ", "                                                               ", "                                                               ", "                                                               ", "                                                               ", "                                                               ", "                                                               ", "                                                               ", "                                                               ", "                                                               ", "                                                               ", "                                                               ", "                                                               ", "                                                               ", "                                                               ", "                                                               ", "                                                               ", "                                                               ", "                                                               ", "                                                               ") 
        .aisle("  BHHLLLHHBDDDMMMDDDDBBOOOBDDDBEBDDDBOOOBBDDDDMMMDDDBHHLLLHHB  ", "           CCINNNIILL      LDD   DDL      LLIINNNICC           ", "            FJNNNIILL      LDD   DDL      LLIINNNJF            ", "           CCINNNIILL      LDD   DDL      LLIINNNICC           ", "          BDDDMMMDDDDBB   BDDBCCCBDDB   BBDDDDMMMDDDB          ", "           BPPPPPPPBB      BB GGG BB      BBPPPPPPPB           ", "              B CIBBBFFFFFFB  GGG  BFFFFFFBBBIC B              ", "              C FIBBB   C     GGG     C   BBBIF C              ", "              C CIBBB         GGG         BBBIC C              ", "              CBBH            CEC            HBBC              ", "                              HBH                              ", "                                                               ", "                                                               ", "                                                               ", "                             C   C                             ", "                                                               ", "                                                               ", "                                                               ", "                                                               ", "                                                               ", "                                                               ", "                                                               ", "                                                               ", "                                                               ", "                                                               ", "                                                               ", "                                                               ", "                                                               ", "                                                               ", "                                                               ", "                                                               ", "                                                               ", "                                                               ", "                                                               ", "                                                               ", "                                                               ", "                                                               ", "                                                               ", "                                                               ", "                                                               ", "                                                               ", "                                                               ", "                                                               ", "                                                               ", "                                                               ", "                                                               ", "                                                               ", "                                                               ", "                                                               ", "                                                               ", "                                                               ", "                                                               ", "                                                               ", "                                                               ", "                                                               ", "                                                               ", "                                                               ", "                                                               ", "                                                               ", "                                                               ", "                                                               ", "                                                               ", "                                                               ") 
        .aisle("  BHLLLHHBDDDMMMDDDBBOOOOOBDDDBEBDDDBOOOOOBBDDDMMMDDDBHHLLLHB  ", "          CCINNNILL        LDD   DDL        LLINNNICC          ", "           FINNIILL        LDD   DDL        LLINNNIF           ", "          CCINNIILL        LDD   DDL        LLINNNICC          ", "         BDDDMMMDDDBB     BDDBCKCBDDB     BBDDDMMMDDDB         ", "          BPPPPPPPB        BB GGG BB        BPPPPPPPB          ", "          C   BCIBBFFFFFFFFB  GGG  BFFFFFFFFBBICB   C          ", "              BCJB CC   C     GGG     C   CC BJCB              ", "              BCIB            GGG            BICB              ", "             CBBH             CEC             HBBC             ", "              C               HBH               C              ", "                                                               ", "                                                               ", "                                                               ", "                                                               ", "                             C   C                             ", "                             C   C                             ", "                                                               ", "                                                               ", "                                                               ", "                                                               ", "                                                               ", "                                                               ", "                                                               ", "                                                               ", "                                                               ", "                                                               ", "                                                               ", "                                                               ", "                                                               ", "                                                               ", "                                                               ", "                                                               ", "                                                               ", "                                                               ", "                                                               ", "                                                               ", "                                                               ", "                                                               ", "                                                               ", "                                                               ", "                                                               ", "                                                               ", "                                                               ", "                                                               ", "                                                               ", "                                                               ", "                                                               ", "                                                               ", "                                                               ", "                                                               ", "                                                               ", "                                                               ", "                                                               ", "                                                               ", "                                                               ", "                                                               ", "                                                               ", "                                                               ", "                                                               ", "                                                               ", "                                                               ", "                                                               ") 
        .aisle(" BHHLLHHBDDDMMDDDDBOOOOOBBBDDDBEBDDDBBBOOOOOBDDDDMMDDDBHHLLHHB ", "         CCINNILLL        LDDD   DDDL        LLIINNICC         ", "          FJNNILLL        LDDD   DDDL        LLIINNJF          ", "         CCINNILLL        LDDD   DDDL        LLIINNICC         ", "        BDDDMMDDDDB     JBBDDBCACBDDBBJ     BDDDDMMDDDB        ", "         BPPPPPPBB         BB GGG BB         BBPPPPPPB         ", "           B CBIBBFFFFFFFFFB  GGG  BFFFFFFFFFBBIBC B           ", "           C FBIB   C   C     GGG     C   C   BIBF C           ", "           C CBIB             GGG             BIBC C           ", "           CCBHH              CEC              HHBCC           ", "                              HBH                              ", "               C                               C               ", "                                                               ", "                                                               ", "                                                               ", "                                                               ", "                                                               ", "                             CC CC                             ", "                             C C C                             ", "                             CC CC                             ", "                                                               ", "                                                               ", "                                                               ", "                                                               ", "                                                               ", "                                                               ", "                                                               ", "                                                               ", "                                                               ", "                                                               ", "                                                               ", "                                                               ", "                                                               ", "                                                               ", "                                                               ", "                                                               ", "                                                               ", "                                                               ", "                                                               ", "                                                               ", "                                                               ", "                                                               ", "                                                               ", "                                                               ", "                                                               ", "                                                               ", "                                                               ", "                                                               ", "                                                               ", "                                                               ", "                                                               ", "                                                               ", "                                                               ", "                                                               ", "                                                               ", "                                                               ", "                                                               ", "                                                               ", "                                                               ", "                                                               ", "                                                               ", "                                                               ", "                                                               ") 
        .aisle(" BHLLHHBDDDMMDDDBBOOOOBBOOBDDDBEBDDDBOOBBOOOOBBDDDMMDDDBHHLLHB ", "        CCINNILL           LDD   DDL           LLINNICC        ", "         FINNILL           LDD   DDL           LLINNIF         ", "        CCINNILL           LDD   DDL           LLINNICC        ", "       BDDDMMDDDBB    JJ  BDDBCCCBDDB  JJ    BBDDDMMDDDB       ", "        BPPPPPPB           BB  C  BB           BPPPPPPB        ", "            BIBBFFFFFFFFFFFB       BFFFFFFFFFFFBBIB            ", "            BJBB    CC   C           C   CC    BBJB            ", "            BIBB                               BBIB            ", "           CBH                CEC                HBC           ", "                              HBH                              ", "                                                               ", "                C                             C                ", "                C                             C                ", "                                                               ", "                                                               ", "                                                               ", "                                                               ", "                                                               ", "                                                               ", "                             C   C                             ", "                             C   C                             ", "                             C   C                             ", "                                                               ", "                                                               ", "                                                               ", "                                                               ", "                                                               ", "                                                               ", "                                                               ", "                                                               ", "                                                               ", "                                                               ", "                                                               ", "                                                               ", "                                                               ", "                                                               ", "                                                               ", "                                                               ", "                                                               ", "                                                               ", "                                                               ", "                                                               ", "                                                               ", "                                                               ", "                                                               ", "                                                               ", "                                                               ", "                                                               ", "                                                               ", "                                                               ", "                                                               ", "                                                               ", "                                                               ", "                                                               ", "                                                               ", "                                                               ", "                                                               ", "                                                               ", "                                                               ", "                                                               ", "                                                               ", "                                                               ") 
        .aisle(" BHLHHBDDDMMDDDBOOOOBBOOOOBDDDBEBDDDBOOOOBBOOOOBDDDMMDDDBHHLHB ", "       CCINNILL            LDD   DDL            LLINNICC       ", "        FJNNILL            LDD   DDL            LLINNJF        ", "       CCINNILL            LDD   DDL            LLINNICC       ", "      BDDDMMDDDB    JJ    BDDBCCCBDDB    JJ    BDDDMMDDDB      ", "       BPPPPPPB            BB GGG BB            BPPPPPPB       ", "           CIBBFFFFFFFFFFFFB  GGG  BFFFFFFFFFFFFBBIC           ", "           FJB CC    C   C    GGG    C   C    CC BJF           ", "           CIB                GGG                BIC           ", "          CBH                 CEC                 HBC          ", "                              HBH                              ", "                                                               ", "                                                               ", "                                                               ", "                 C                           C                 ", "                 C                           C                 ", "                                                               ", "                                                               ", "                                                               ", "                                                               ", "                                                               ", "                                                               ", "                            BBBBBBB                            ", "                            BCCBCCB                            ", "                            BFCBCFB                            ", "                            BCCBCCB                            ", "                            BBBBBBB                            ", "                                                               ", "                                                               ", "                                                               ", "                                                               ", "                                                               ", "                                                               ", "                                                               ", "                                                               ", "                                                               ", "                                                               ", "                                                               ", "                                                               ", "                                                               ", "                                                               ", "                                                               ", "                                                               ", "                                                               ", "                                                               ", "                                                               ", "                                                               ", "                                                               ", "                                                               ", "                                                               ", "                                                               ", "                                                               ", "                                                               ", "                                                               ", "                                                               ", "                                                               ", "                                                               ", "                                                               ", "                                                               ", "                                                               ", "                                                               ", "                                                               ", "                                                               ") 
        .aisle(" BHHHBDDDMMDDDBOOOOBOOOOOBDDDDBEBDDDDBOOOOOBOOOOBDDDMMDDDBHHHB ", "      CCINNILL            LDDD   DDDL            LLINNICC      ", "       FINNILL            LDDD   DDDL            LLINNIF       ", "      CCINNILL            LDDD   DDDL            LLINNICC      ", "     BDDDMMDDDB    J     BDDDBCKCBDDDB     J    BDDDMMDDDB     ", "      BPPPPPPB            BBB GGG BBB            BPPPPPPB      ", "       BBBBBBBFFFFFFFFFFFFBB  GGG  BBFFFFFFFFFFFFBBBBBBB       ", "        CCBBB   CC   CC  C    GGG    C  CC   CC   BBBCC        ", "         CBBB                 GGG                 BBBC         ", "         CBH                   C                   HBC         ", "          C                   CEC                   C          ", "                              HBH                              ", "                                                               ", "                                                               ", "                 C                           C                 ", "                                                               ", "                  C                         C                  ", "                  C                         C                  ", "                                                               ", "                                                               ", "                                                               ", "                                                               ", "                        BBBBBBBBBBBBBBB                        ", "                        CBCCBIIBIIBCCBC                        ", "                         BFCBJIBIJBCFB                         ", "                        CBCCBIIBIIBCCBC                        ", "                        BBBBBBBBBBBBBBB                        ", "                            C     C                            ", "                            C     C                            ", "                            CC   CC                            ", "                            CC   CC                            ", "                              C C                              ", "                              C C                              ", "                               C                               ", "                               C                               ", "                             CCCCC                             ", "                               C                               ", "                               C                               ", "                                                               ", "                                                               ", "                                                               ", "                                                               ", "                                                               ", "                                                               ", "                                                               ", "                                                               ", "                                                               ", "                                                               ", "                                                               ", "                                                               ", "                                                               ", "                                                               ", "                                                               ", "                                                               ", "                                                               ", "                                                               ", "                                                               ", "                                                               ", "                                                               ", "                                                               ", "                                                               ", "                                                               ", "                                                               ") 
        .aisle(" BHHBBDDMMMDDBOOOOBOOOOBBDDDDDBEBDDDDDBBOOOOBOOOOBDDMMMDDBBHHB ", "      CINNNIL            LDDDD   DDDDL            LLNNNIC      ", "      FJNNNIL            LDDDD   DDDDL            LLINNJF      ", "      CINNNIL            LDDDD   DDDDL            LLINNICC     ", "     BDDMMMDDB    J    BBDDDDBCACBDDDDBB    J    BDDMMMDDB     ", "      BPPPPPB            BBBB GGG BBBB            BPPPPPB      ", "          CIBFFFFFFFFFFFFB    GGG    BFFFFFFFFFFFFBIC          ", "          CIBC   CC   CC      GGG      CC   CC   CBIC          ", "          CIB                 GGG                 BIC          ", "        CBBH                   C                   HBBC        ", "                              CEC                              ", "           C                  HBH                  C           ", "                                                               ", "                                                               ", "                                                               ", "                 C                           C                 ", "                                                               ", "                                                               ", "                   C                       C                   ", "                   C                       C                   ", "                                                               ", "                                                               ", "                      BBBBBBLLLLLLLBBBBBB                      ", "                      BCCBIINNNNNNNIIBCCB                      ", "                      BFCBJINNNNNNNIJBCFB                      ", "                      BCCBIINNNNNNNIIBCCB                      ", "                      BBBBBBLLLLLLLBBBBBB                      ", "                        C             C                        ", "                        C             C                        ", "                        C             C                        ", "                        C             C                        ", "                           CC     CC                           ", "                            C     C                            ", "                           CC     CC                           ", "                            C     C                            ", "                            C     C                            ", "                                                               ", "                                                               ", "                              C C                              ", "                              C C                              ", "                                                               ", "                                                               ", "                                                               ", "                                                               ", "                                                               ", "                                                               ", "                                                               ", "                                                               ", "                                                               ", "                                                               ", "                                                               ", "                                                               ", "                                                               ", "                                                               ", "                                                               ", "                              C C                              ", "                              C C                              ", "                              C C                              ", "                              C C                              ", "                              C C                              ", "                             C   C                             ", "                             C   C                             ", "                             C   C                             ") 
        .aisle(" BHHBDDMMMDDBOOOOBOOOBBDDDDCCCBEBCCCDDDDBBOOOBOOOOBDDMMMDDBHHB ", "     CINNNIL           LLDD         DDLL           LINNNIC     ", "     CINNNIL           LLDD         DDLL           LINNNIC     ", "     CINNNIL           LLDD         DDLL           LINNNIC     ", "    BDDMMMDDB    J   BBDDDDCCBCCCBCCDDDDBB   J    BDDMMMDDB    ", "     BPPPPPB           BBBB    C    BBBB           BPPPPPB     ", "         CIBFFFFFFFFFFFBB             BBFFFFFFFFFFFBIC         ", "         FJB CC   CC                       CC   CC BJF         ", "         CIB                                       BIC         ", "        CBH                    C                    HBC        ", "                              CEC                              ", "                              HBH                              ", "            C                                     C            ", "            C                                     C            ", "                                                               ", "                                                               ", "                C                             C                ", "                 C                           C                 ", "                  C                         C                  ", "                                                               ", "                    C                     C                    ", "                    C                     C                    ", "                    CBBBBLLLLLLLLLLLLLBBBBC                    ", "                     CBIINNNNNNNNNNNNNIIBC                     ", "                      BJINNNNNNNNNNNNNIJB                      ", "                     CBIINNNNNNNNNNNNNIIBC                     ", "                     BBBBLLLLLLLLLLLLLBBBB                     ", "                                                               ", "                                                               ", "                                                               ", "                                                               ", "                        CC           CC                        ", "                        C C         C C                        ", "                        CC           CC                        ", "                        C             C                        ", "                                                               ", "                            C     C                            ", "                           CC     CC                           ", "                            C     C                            ", "                           CC     CC                           ", "                              C C                              ", "                              C C                              ", "                                                               ", "                                                               ", "                                                               ", "                                                               ", "                                                               ", "                                                               ", "                                                               ", "                                                               ", "                                                               ", "                           C   C   C                           ", "                           C   C   C                           ", "                           C   C   C                           ", "                           C   C   C                           ", "                          C         C                          ", "                          C         C                          ", "                          C         C                          ", "                          C   C C   C                          ", "                          C BBBBBBB C                          ", "                          C         C                          ", "                          C BBBBBBB C                          ", "                          C  C   C  C                          ") 
        .aisle(" BHBBDDMMDDDBOOOBOOOBDDDDCCCCCBEBCCCCCDDDDBOOOBOOOBDDDMMDDBBHB ", "     CINNILL         LLDD             DDLL         LLINNIC     ", "     FJNNILL         LLDD             DDLL         LLINNJF     ", "     CINNILL         LLDD             DDLL         LLINNIC     ", "    BDDMMDDDB   J   BDDDDCCCCBCCCBCCCCDDDDB   J   BDDDMMDDB    ", "     BPPPPPB         BBBB     GGG     BBBB         BPPPPPB     ", "        CIBBFFFFFFFFFBB       GGG       BBFFFFFFFFFBBIC        ", "        CIB   CC   CC         GGG         CC   CC   BIC        ", "        CIB                   GGG                   BIC        ", "       CBH                     C                     HBC       ", "                              CEC                              ", "                             HHBHH                             ", "                                                               ", "                                                               ", "             CC                                 CC             ", "             C C                               C C             ", "                                                               ", "                C                             C                ", "                                                               ", "                                                               ", "                                                               ", "                                                               ", "                    BBBLLLLLFFFFFFFLLLLLBBB                    ", "                    CCBNNNNNNNNNNNNNNNNNBCC                    ", "                     FBNNNNNNNNNNNNNNNNNBF                     ", "                    CCBNNNNNNNNNNNNNNNNNBCC                    ", "                    BBBLLLLLFFFFFFFLLLLLBBB                    ", "                                                               ", "                                                               ", "                                                               ", "                                                               ", "                                                               ", "                                                               ", "                                                               ", "                                                               ", "                        C             C                        ", "                        C             C                        ", "                        CC           CC                        ", "                        C C         C C                        ", "                        CC           CC                        ", "                            C     C                            ", "                            C     C                            ", "                            CC   CC                            ", "                            CC   CC                            ", "                             C   C                             ", "                             C   C                             ", "                            CC   CC                            ", "                            C C C C                            ", "                            C C C C                            ", "                            C C C C                            ", "                            C C C C                            ", "                                                               ", "                                                               ", "                                                               ", "                                                               ", "                                                               ", "                                                               ", "                       C               C                       ", "                       C  C         C  C                       ", "                       C BBBHHHHHHHBBB C                       ", "                       C    FFFFFFF    C                       ", "                       C BBBHHHHHHHBBB C                       ", "                       C  C  C   C  C  C                       ") 
        .aisle("  BBDDMMMDDBOOOBOOOBDDDCCCCCDDBEBDDCCCCCDDDBOOOBOOOBDDMMMDDBB  ", "    CINNNIL         LDD     DD   DD     DDL         LINNNIC    ", "    CINNNIL         LDD     DD   DD     DDL         LINNNIC    ", "    CINNNIL         LDD     DD   DD     DDL         LINNNIC    ", "   BDDMMMDDB   J   BDDDCCCCCDBCKCBDCCCCCDDDB   J   BDDMMMDDB   ", "    BPPPPPB         BBB     B GGG B     BBB         BPPPPPB    ", "     BBBBBBFFFFFFFFFB         GGG         BFFFFFFFFFBBBBBB     ", "      CBBB     CC             GGG             CC     BBBC      ", "      CBBB                    GGG                    BBBC      ", "      CBH                      C                      HBC      ", "                             CCECC                             ", "                           HHBBBBBHH                           ", "                                                               ", "                                                               ", "                                                               ", "                                                               ", "              C                                 C              ", "              C                                 C              ", "                C                             C                ", "                                                               ", "                                                               ", "                                                               ", "                   BBBLLLLFFLLLLLLLFFLLLLBBB                   ", "                   CCINNNNNNNNNNNNNNNNNNNICC                   ", "                    FJNNNNNNNNNNNNNNNNNNNJF                    ", "                   CCINNNNNNNNNNNNNNNNNNNICC                   ", "                   BBBLLLLFFLLLLLLLFFLLLLBBB                   ", "                     C                   C                     ", "                     C                   C                     ", "                     C                   C                     ", "                                                               ", "                                                               ", "                                                               ", "                                                               ", "                                                               ", "                       C               C                       ", "                                                               ", "                                                               ", "                                                               ", "                                                               ", "                        C             C                        ", "                        C             C                        ", "                        C             C                        ", "                        C  BBBBBBBBB  C                        ", "                        C    B   B    C                        ", "                        C    B   B    C                        ", "                        C  BBBBBBBBB  C                        ", "                                                               ", "                                                               ", "                                                               ", "                                                               ", "                                                               ", "                                                               ", "                                                               ", "                                                               ", "                      C                 C                      ", "                      C                 C                      ", "                                                               ", "                       C               C                       ", "                       BBHHHFFFFFFFHHHBB                       ", "                         FFFNNNNNNNFFF                         ", "                        BHHHFFFFFFFHHHB                        ", "                        C C  C   C  C C                        ") 
        .aisle("  BBDDMMDDBOOOBOOOBDDDCCCCDDDDBEBDDDDCCCCDDDBOOOBOOOBDDMMDDBB  ", "    CINNIL         LDD    DDDD   DDDD    DDL         LINNIC    ", "    FJNNIL         LDD    DDDD   DDDD    DDL         LINNJF    ", "    CINNIL         LDD    DDDD   DDDD    DDL         LINNIC    ", "   BDDMMDDB   J   BDDDCCCCDDDBCACBDDDCCCCDDDB   J   BDDMMDDB   ", "    BPPPPB         BBB    BBB GGG BBB    BBB         BPPPPB    ", "       CIBFFFFFFFFFB          GGG          BFFFFFFFFFBIC       ", "       CIBC     CC            GGG            CC     CBJF       ", "       CIB                   CGGGC                   BIC       ", "      CBH                    C C C                    HBC      ", "                             CCECC                             ", "                         HHBBBBBBBBBHH                         ", "                                                               ", "                                                               ", "                                                               ", "                                                               ", "                                                               ", "                                                               ", "               C                               C               ", "               C                               C               ", "                                                               ", "                                                               ", "                  BBBLLLFFLLLLLLLLLLLFFLLLBBB                  ", "                  CBBNNNNNNNNNNNNNNNNNNNNNBBC                  ", "                   BBNNNNNNNNNNNNNNNNNNNNNBB                   ", "                  CBBNNNNNNNNNNNNNNNNNNNNNBBC                  ", "                  BBBLLLFFLLLLLLLLLLLFFLLLBBB                  ", "                                                               ", "                                                               ", "                                                               ", "                     C                   C                     ", "                     C                   C                     ", "                                                               ", "                                                               ", "                                                               ", "                      C                 C                      ", "                                                               ", "                                                               ", "                       C               C                       ", "                       C               C                       ", "                                                               ", "                                                               ", "                                                               ", "                        BBBDDDDDDDDDBBB                        ", "                        B  OOBOOOBOO  B                        ", "                        B  OOBOOOBOO  B                        ", "                        BBBDDDDDDDDDBBB                        ", "                       C               C                       ", "                       C               C                       ", "                      C                 C                      ", "                      C                 C                      ", "                      C                 C                      ", "                     C                   C                     ", "                     C                   C                     ", "                     C                   C                     ", "                                                               ", "                                                               ", "                                                               ", "                                                               ", "                      BBHFFFFHHHHHFFFFHBB                      ", "                        FNNNNFFFFFNNNNF                        ", "                      BBHFFFFHHHHHFFFFHBB                      ", "                        C C  C   C  C C                        ") 
        .aisle("  BDDMMMDDBOOBOOOBDDDCCCDDDDDBBEBBDDDDDCCCDDDBOOOBOOBDDMMMDDB  ", "   CINNNIL        LDD   DDDOOB   BOODDD   DDL        LINNNIC   ", "   CINNNIL        LDD   DDDOOB   BOODDD   DDL        LINNNIC   ", "   CINNNIL        LDD   DDDOOB   BOODDD   DDL        LINNNIC   ", "  BDDMMMDDB  J   BDDDCCCDDDDDBBBBBDDDDDCCCDDDB   J  BDDMMMDDB  ", "   BPPPPPB        BBB   BBBBB  C  BBBBB   BBB        BPPPPPB   ", "       CIBFFFFFFFFB        BB     BB        BFFFFFFFFBIC       ", "       FJBCCC    C         BBC   CBB         C    CCCBIC       ", "       CIB                 FBC   CBF                 BIC       ", "     CBBH                  BBC C CBB                  HBBC     ", "                           BBBBBBBBB                           ", "                        HBB         BBH                        ", "                                                               ", "                                                               ", "                                                               ", "                                                               ", "                                                               ", "                                                               ", "                                                               ", "                                                               ", "                C                             C                ", "                C                             C                ", "                CBBBLLLFLLLLLBBBBBLLLLLFLLLBBBC                ", "                 CCBNNNNNNNNNIIBIINNNNNNNNNBCC                 ", "                  FBNNNNNNNNNIJBJINNNNNNNNNBF                  ", "                 CCBNNNNNNNNNIIBIINNNNNNNNNBCC                 ", "                 BBBLLLFLLLLLBBBBBLLLLLFLLLBBB                 ", "                             C   C                             ", "                             C   C                             ", "                             C   C                             ", "                             CC CC                             ", "                                                               ", "                    C                     C                    ", "                    C                     C                    ", "                     C                   C                     ", "                     C                   C                     ", "                      C                 C                      ", "                      C                 C                      ", "                                                               ", "                                                               ", "                                                               ", "                                                               ", "                                                               ", "                       BBDDFFFFFFFFFDDBB                       ", "                        BOOMMMMMMMMMOOB                        ", "                        BOOMMMMMMMMMOOB                        ", "                       BBDDFFFFFFFFFDDBB                       ", "                                                               ", "                                                               ", "                                                               ", "                                                               ", "                                                               ", "                                                               ", "                    C                     C                    ", "                                                               ", "                    C                     C                    ", "                    C                     C                    ", "                    C                     C                    ", "                    CC       C   C       CC                    ", "                    CBHHFFHHHBBBBBHHHFFHHBC                    ", "                    C FFNNFFF     FFFNNFF C                    ", "                    CBHHFFHHHBBBBBHHHFFHHBC                    ", "                    C    C   C   C   C    C                    ") 
        .aisle("  BDDMMDDBOOOBOOBDDDCCCDDDBBBBEEEBBBBDDDCCCDDDBOOBOOOBDDMMDDB  ", "   CINNIL        LDD   DDOB  C   C  BODD   DDL        LINNIC   ", "   FJNNIL        LDD   DDOB  C   C  BODD   DDL        LINNJF   ", "   CINNIL        LDD   DDOB  C   C  BODD   DDL        LINNIC   ", "  BDDMMDDB   J  BDDDCCCDDDBBBBEEEBBBBDDDCCCDDDB  J   BDDMMDDB  ", "   BPPPPB        BBB   BBBBJBCQQQCBJBBBB   BBB        BPPPPB   ", "      CIBFFFFFFFFB       BBJBCQQQCBJBB       BFFFFFFFFBIC      ", "      CIB   CCC          BBBBCQQQCBBBB          CCC   BJF      ", "      CIB                FBJB QQQ BJBF                BIC      ", "     CBH                 BBJB QQQ BJBB                 HBC     ", "                         BBBBBCCCBBBBB                         ", "                       HB             BH                       ", "                                                               ", "                                                               ", "                                                               ", "                                                               ", "                                                               ", "                                                               ", "                                                               ", "                                                               ", "                                                               ", "                                                               ", "                BBBLLLFLLLBBBBBBBBBBBLLLFLLLBBB                ", "                CCINNNNNNNIIBCCBCCBIINNNNNNNICC                ", "                 FJNNNNNNNIJBCFBFCBJINNNNNNNJF                 ", "                CCINNNNNNNIIBCCBCCBIINNNNNNNICC                ", "                BBBLLLFLLLBBBBBBBBBBBLLLFLLLBBB                ", "                  C       C         C       C                  ", "                  C       C         C       C                  ", "                  C        C       C        C                  ", "                   C       C       C       C                   ", "                   C        CC C CC        C                   ", "                            CCC CCC                            ", "                             C   C                             ", "                    C        C   C        C                    ", "                    C                     C                    ", "                                                               ", "                                                               ", "                                                               ", "                                                               ", "                                                               ", "                                                               ", "                                                               ", "                     BBDDFFFFFFFFFFFFFDDBB                     ", "                     B OBMMMMMMMMMMMMMBO B                     ", "                     B OBMMMMMMMMMMMMMBO B                     ", "                     BBDDFFFFFFFFFFFFFDDBB                     ", "                                                               ", "                                                               ", "                                                               ", "                                                               ", "                                                               ", "                   C                       C                   ", "                   C                       C                   ", "                   C         CC CC         C                   ", "                             C C C                             ", "                             CC CC                             ", "                            CC   CC                            ", "                    C      C C   C C      C                    ", "                    BHFFFHBBBC   CBBBHFFFHB                    ", "                     FNNNF   C   C   FNNNF                     ", "                    BHFFFHBBBC   CBBBHFFFHB                    ", "                     C   C   C   C   C   C                     ") 
        .aisle(" BDDMMMDDBOOBOOOBDDCCCDDDBEEEBEEEBEEEBDDDCCCDDBOOOBOOBDDMMMDDB ", "  CINNNIL        LD   DDO             ODD   DL        LINNNIC  ", "  CINNNIL        LD   DDO             ODD   DL        LINNNIC  ", "  CINNNIL        LD   DDO             ODD   DL        LINNNIC  ", " BDDMMMDDB  J   BDDCCCDDDBCCCBEEEBCCCBDDDCCCDDB   J  BDDMMMDDB ", "  BPPPPPB        BB   BBBJH C QQQ C HJBBB   BB        BPPPPPB  ", "      CIBFFFFFFFFB      BJH C QQQ C HJB      BFFFFFFFFBIC      ", "      FJB     CC        BBHHCCQQQCCHHBB        CC     BIC      ", "      CIB               FJH C QQQ C HJF               BIC      ", "     CBH                BJH C QQQ C HJB                HBC     ", "                        BBCCCBCKCBCCCBB                        ", "                      HB               BH                      ", "                                                               ", "                                                               ", "                                                               ", "                                                               ", "                                                               ", "                                                               ", "                                                               ", "                                                               ", "                             C   C                             ", "                             C   C                             ", "               BBBLLLFLLLBBBBC   CBBBBLLLFLLLBBB               ", "               BBBNNNNNNNBCCB     BCCBNNNNNNNBBB               ", "               BBBNNNNNNNBCFB     BFCBNNNNNNNBBB               ", "               BBBNNNNNNNBCCB     BCCBNNNNNNNBBB               ", "               BBBLLLFLLLBBBB     BBBBLLLFLLLBBB               ", "                                                               ", "                                                               ", "                                                               ", "                                                               ", "                                                               ", "                                                               ", "                                                               ", "                                                               ", "                   C         C   C         C                   ", "                    C        C   C        C                    ", "                    C        CC CC        C                    ", "                             C C C                             ", "                                                               ", "                                                               ", "                                                               ", "                                                               ", "                     BDFFFFFFDDDDDFFFFFFDB                     ", "                      OMMMMMMBOOOBMMMMMMO                      ", "                      OMMMMMMBOOOBMMMMMMO                      ", "                     BDFFFFFFDDDDDFFFFFFDB                     ", "                                                               ", "                                                               ", "                   C                       C                   ", "                   C         C C C         C                   ", "                   C         CC CC         C                   ", "                            CC   CC                            ", "                             C   C                             ", "                                                               ", "                  C                         C                  ", "                  C                         C                  ", "                                                               ", "                         C           C                         ", "                   BHFFHHB           BHHFFHB                   ", "                    FNNFF             FFNNF                    ", "                   BHFFHHB           BHHFFHB                   ", "                      C  C           C  C                      ") 
